Workbook
Name Category: #REF!
Name Transaction: #REF!

Sheet Reloc
G1: Data Before
G2: RF 1 | I2: RF 2 | K2: RF 3 | M2: RF 4 | O2: AAU 1 | Q2: AAU 2 | S2: AAU 3 | U2: MW 1 | X2: MW 2 | AA2: MW 3 | AD2: MW 4
A3: NO | B3: Site ID Old | C3: Site Name Old | D3: Tenant | E3: Site ID Tenant | F3: Site Name Tenant | G3: Height | H3: Azimuth | I3: Height2 | J3: Azimuth3 | K3: Height4 | L3: Azimuth5 | M3: Height6 | N3: Azimuth7 | O3: Height8 | P3: Azimuth9 | Q3: Height10 | R3: Azimuth11 | S3: Height12 | T3: Azimuth13 | U3: Link | V3: Height14 | W3: Azimuth15 | X3: Link16 | Y3: Height17 | Z3: Azimuth18 | AA3: Link19 | AB3: Height20 | AC3: Azimuth21 | AD3: Link22 | AE3: Height23 | AF3: Azimuth24 | AG3: Site ID New | AH3: Site Name New | AI3: LATITUDE | AJ3: LONGITUDE | AK3: CR // CRQ // XLWO | AL3: Start Dismantle | AM3: Start Reinstall | AN3: OA | AO3: Data After
A4: 1 | B4: R1200302 | C4: BANGUN PURBA | D4: XLS | E4: SUM-SU-LBP-0405 | F4: BANGUN PURBA Relocation | G4: 69 | H4: 0 | I4: 69 | J4: 180 | K4: 69 | L4: 280 | U4: to SUM-SU-LBP-0023 | V4: 54 | W4: 130 | X4: to SUM-SU-SRH-1245 | Y4: 52 | Z4: 190 | AA4: to SUM-SU-LBP-0022 | AB4: 52 | AC4: 120 | AD4: to SUM-SU-SRH-8224 | AE4: 53 | AF4: 240 | AG4: ID-SU-03892 | AH4: BANGUN PURBA | AI4: 3.37141 | AJ4: 98.8149 | AK4: XLWO-20260522-00000051 | AL4: 46168 | AM4: 46169 | AN4: 46171 | AO4: RF 1 | AQ4: RF 2 | AS4: RF 3 | AU4: RF 4 | AW4: AAU 1 | AY4: AAU 2 | BA4: AAU 3 | BC4: MW 1 | BF4: MW 2 | BI4: MW 3 | BL4: MW 4
A5: 2 | B5: R3350421 | C5: KARANGJUNTI | D5: IOH | E5: 14BRS0006 | F5: KARANGJUNTI_CM | G5: 53 | H5: 120 | I5: 53 | J5: 215 | K5: 53 | L5: 340 | AG5: ID-JT-17956 | AH5: LOSARI KARANGJUNTI | AI5: -6.91628 | AJ5: 108.7941 | AK5: CR-20260529-00000297 | AL5: 46176 | AM5: 46179 | AN5: 46181 | AO5: Height | AP5: Azimuth | AQ5: Height | AR5: Azimuth | AS5: Height | AT5: Azimuth | AU5: Height | AV5: Azimuth | AW5: Height | AX5: Azimuth | AY5: Height | AZ5: Azimuth | BA5: Height | BB5: Azimuth | BC5: Link | BD5: Height | BE5: Azimuth | BF5: Link | BG5: Height | BH5: Azimuth | BI5: Link | BJ5: Height | BK5: Azimuth | BL5: Link | BM5: Height | BN5: Azimuth
A6: 3 | B6: R3350421 | C6: KARANGJUNTI | D6: XLS | E6: JAW-JT-BBS-0007 | F6: KARANGJUNTI Relocation | G6: 68 | H6: 0 | I6: 68 | J6: 160 | K6: 68 | L6: 310 | AG6: ID-JT-17956 | AH6: LOSARI KARANGJUNTI | AI6: -6.91429 | AJ6: 108.7941 | AK6: XLWO-20260619-00006228 | AL6: 46195 | AM6: 46196 | AN6: 46200 | AO6: 68 | AP6: 0 | AQ6: 68 | AR6: 180 | AS6: 68 | AT6: 280 | BC6: to SUM-SU-LBP-0023 | BD6: 54 | BE6: 130 | BF6: SUM-SU-SRH-1245 | BG6: 51 | BH6: 190 | BI6: to SUM-SU-LBP-0022 | BJ6: 60 | BK6: 120 | BL6: to SUM-SU-SRH-8224 | BM6: 53 | BN6: 240
A7: 4 | B7: E3200525 | C7: GEDUNG_LIPPO | D7: IOH | E7: 13BDG0292 | F7: IMGEDUNG_LIPPO_EP | G7: 3 | H7: 30 | AG7: ID-JB-03467 | AH7: PAKUHAJI WETAN NGAMPRAH | AI7: -6.82802 | AJ7: 10754079 | AL7: 45911 | AO7: 53 | AP7: 30 | AQ7: 53 | AR7: 120 | AS7: 53 | AT7: 240 | BC7: to 14BRS0013 | BD7: 51 | BE7: 40
A8: 5 | B8: E8200008 | C8: JAILOLO | D8: IOH | E8: 32HBR0001 | F8: JAILOLO_EP | G8: 58 | H8: 10 | I8: 58 | J8: 180 | K8: 58 | L8: 235 | U8: to 32HBR0002 | V8: 54 | W8: 35 | X8: to 32HBR0011 | Y8: 33 | Z8: 75 | AA8: to 32TER0004 main | AB8: 44 | AC8: 200 | AD8: to 32TER0004 standby | AE8: 29 | AF8: 200 | AG8: ID-MU-14641 | AH8: GUAEMAADU JAILOLO | AI8: 1.06156 | AJ8: 127.46364 | AK8: CR-20251215-00000284 | AL8: 46007 | AM8: 46012 | AN8: 46023
A9: 6 | B9: R3270681 | C9: JAPARA KUNINGAN | D9: XLS | E9: JAW-JB-KNG-1359 | F9: JAPARA KUNINGAN | AG9: E3200649 | AH9: JAPARA | AI9: -6.89649 | AJ9: 108.51681 | AO9: 47 | AP9: 20
A10: 7 | B10: E3200182 | C10: GEULIS_RESORT | D10: XLS | E10: JAW-JB-CBI-0515 | F10: GEULIS RESORT BOGOR | G10: 51 | H10: 190 | I10: 51 | J10: 270 | K10: 51 | L10: 320 | U10: to JAW-JB-BGR-0421 | V10: 49 | W10: 280 | AG10: ID-JB-14444 | AH10: GEULIS SUKARAJA | AI10: -6.6318 | AJ10: 106.8663 | AK10: XLWO-20260804-00000177 | AL10: 46244 | AM10: 46245 | AO10: 60 | AP10: 45 | AQ10: 60 | AR10: 190 | AS10: 60 | AT10: 240 | BC10: to 32HBR0002 | BD10: 71 | BE10: 10 | BF10: to 32HBR0011 | BG10: 55 | BH10: 110 | BI10: to 32TER0004 main | BJ10: 50 | BK10: 205 | BL10: to 32TER0004 standby | BM10: 80 | BN10: 205
A11: 8 | B11: E3200182 | C11: GEULIS_RESORT | D11: IOH | E11: 13CBN0771 | F11: GEULIS_RESORT_EP | G11: 67 | H11: 20 | I11: 67 | J11: 210 | K11: 67 | L11: 320 | AG11: ID-JB-14444 | AH11: GEULIS SUKARAJA | AI11: -6.6318 | AJ11: 106.8663 | AK11: CR-20260804-00000400 CR-20260804-00000411
A12: 9 | B12: R3270184 | C12: SETRAINDAH BARAT | D12: IOH | E12: 13BDG0084 | F12: SETRAINDAHBARAT_CM | G12: 18 | H12: 90 | I12: 18 | J12: 150 | K12: 18 | L12: 330 | AO12: 70 | AQ12: 70 | AS12: 70
A13: 10 | B13: R3270184 | C13: SETRAINDAH BARAT | D13: XLS | E13: JAW-JB-BDG-0045 | F13: SETRA INDAH BARAT | G13: 18 | H13: 30 | I13: 18 | J13: 130 | K13: 18 | L13: 320 | O13: 18 | P13: 50 | Q13: 18 | R13: 230 | S13: 18 | T13: 330 | AO13: 70 | AQ13: 70 | AS13: 70

Sheet Account
A1: No | B1: Account Project | C1: Vendor | D1: Project | E1: Coverage Area
A2: 1 | B2: SGP-TI-Nasional | C2: PT. Sempurna Global Pertama | D2: Telkom Infra | E2: Nasional
A3: 2 | B3: SGI-ZTE_XLSmart-Nasional | C3: PT. Star Global Indonesia | D3: ZTE_XLSmart | E3: Nasional
A4: 3 | B4: CMI-RBLD-Nasional | C4: PT. Centratama Menara Indonesi | D4: Rebuild | E4: Nasional
A5: 4 | B5: CMI-TMAIN-Nasional | C5: PT. Centratama Menara Indonesi | D5: Tower Maintenance | E5: Nasional
A6: 5 | B6: CMI-COLO-Nasional | C6: PT. Centratama Menara Indonesi | D6: Colocation | E6: Nasional
A7: 6 | B7: CMI-MAC-Nasional | C7: PT. Centratama Menara Indonesi | D7: MAC | E7: Nasional
A8: 7 | B8: MSG-RTGS-Bengkulu | C8: PT. Mitra Sistematika Global | D8: Remote Terminal Ground Segment | E8: Bengkulu
A9: 8 | B9: DMT-All-Nasional | C9: PT. Dayamitra Telekomunikasi | D9: All | E9: Nasional
A10: 9 | B10: CCSI-XLS_PLN-EJ | C10: PT. China Comservice Indonesia | D10: XLSmart_PLN | E10: East Java
A11: 10 | B11: MSG-COLO_IOH-Nasional | C11: PT. Mitra Sistematika Global | D11: Colocation_IOH | E11: Nasional
A12: 11 | B12: MSG-STH-Kalimantan | C12: PT. Mitra Sistematika Global | D12: Strengthening | E12: Kalimantan
A13: 12 | B13: CMI-TIP-Nasional | C13: PT. Centratama Menara Indonesia | D13: Tower Inspection Preventive | E13: Nasional
... A17: 16 | B17: CCSI-XLS_PLN-Sulawesi | C17: PT. China Comservice Indonesia | D17: XLSmart_PLN | E17: Sulawesi
A18: =+A17+1 -> 17 | B18: CMI-RLC-Nasional | C18: PT. Centratama Menara Indonesi | D18: Relocation | E18: Nasional
A19: =+A18+1 -> 18 | B19: CMI-SURGE-Nasional | C19: PT. Centratama Menara Indonesi | D19: SURGE | E19: Nasional

Sheet List Material Inbound
B4: Site ID | C4: Site Name | D4: Tenant | E4: Material | F4: UoM | G4: Qty | H4: SN | I4: Remark | J4: Inbound
B5: E3500375 | C5: MERPATI | D5: XLS | E5: Rack Recty | F5: unit | G5: 1
B6: E3500375 | C6: MERPATI | D6: XLS | E6: Recty EATON | F6: unit | G6: 1
B7: E3500375 | C7: MERPATI | D7: XLS | E7: Module recty | F7: pcs | G7: 6
B8: E3500375 | C8: MERPATI | D8: XLS | E8: RTN Huawei 950 | F8: unit | G8: 1
B9: E3500375 | C9: MERPATI | D9: XLS | E9: CSHU + 1 SFP | F9: unit | G9: 1
B10: E3500375 | C10: MERPATI | D10: XLS | E10: Fan RTN 950 | F10: unit | G10: 1
B11: E3500375 | C11: MERPATI | D11: XLS | E11: ISU 2 | F11: pcs | G11: 1
B12: E3500375 | C12: MERPATI | D12: XLS | E12: DCPD | F12: pcs | G12: 2
B13: E3500375 | C13: MERPATI | D13: XLS | E13: Kabel DCPD biru | F13: tarikan | G13: 4
B14: E3500375 | C14: MERPATI | D14: XLS | E14: Kabel DCPD hitam | F14: tarikan | G14: 4
B15: E3500375 | C15: MERPATI | D15: XLS | E15: BBU V9200 | F15: unit | G15: 1 | H15: 219634374099
B16: E3500375 | C16: MERPATI | D16: XLS | E16: VBPe2q | F16: pcs | G16: 1
B17: E3500375 | C17: MERPATI | D17: XLS | E17: VPDc1 | F17: pcs | G17: 1
B18: E3500375 | C18: MERPATI | D18: XLS | E18: VEMC4 | F18: pcs | G18: 1
B19: E3500375 | C19: MERPATI | D19: XLS | E19: VBPE3q | F19: pcs | G19: 1
B20: E3500375 | C20: MERPATI | D20: XLS | E20: VSWd1 | F20: pcs | G20: 1
B21: E3500375 | C21: MERPATI | D21: XLS | E21: SFP (VBPE2q) | F21: pcs | G21: 6
B22: E3500375 | C22: MERPATI | D22: XLS | E22: SFP (VBPE3q) | F22: pcs | G22: 5
B23: E3500375 | C23: MERPATI | D23: XLS | E23: SFP (VSWd1) | F23: pcs | G23: 2
B24: E3500375 | C24: MERPATI | D24: XLS | E24: Casing GPS | F24: pcs | G24: 1
B25: E3500375 | C25: MERPATI | D25: XLS | E25: LPU2 | F25: pcs | G25: 1 | H25: 219639300831
B26: E3500375 | C26: MERPATI | D26: XLS | E26: BLP2 | F26: pcs | G26: 2 | H26: 200145 200343
B27: E3500375 | C27: MERPATI | D27: XLS | E27: SCU | F27: pcs | G27: 1 | H27: 21964195814
B28: E3500375 | C28: MERPATI | D28: XLS | E28: 2XCTN 6120H-SC | F28: pcs | G28: 1 | H28: D80AE69CFF38
B29: E3500375 | C29: MERPATI | D29: XLS | E29: SFP (2XCTN) | F29: pcs | G29: 3
B30: E3500375 | C30: MERPATI | D30: XLS | E30: PW1DC (2XCTN) | F30: pcs | G30: 2
B31: E3500375 | C31: MERPATI | D31: XLS | E31: Battery ZTE ZXESM R311 | F31: pcs | G31: 3
B32: E3500375 | C32: MERPATI | D32: XLS | E32: Kabel power batt (biru) | F32: tarikan | G32: 3
B33: E3500375 | C33: MERPATI | D33: XLS | E33: Kabel power batt (hitam) | F33: tarikan | G33: 3
B34: E3500375 | C34: MERPATI | D34: XLS | E34: Kabel grounding batt | F34: tarikan | G34: 3
B35: E3500375 | C35: MERPATI | D35: XLS | E35: Kabel power BBU (biru-hitam) | F35: tarikan | G35: 1
B36: E3500375 | C36: MERPATI | D36: XLS | E36: Kabel power RTN 950 (biru-hitam) | F36: tarikan | G36: 1
B37: E3500375 | C37: MERPATI | D37: XLS | E37: Kabel power AAU | F37: tarikan | G37: 3
B38: E3500375 | C38: MERPATI | D38: XLS | E38: Kabel power RRU | F38: tarikan | G38: 5
B39: E3500375 | C39: MERPATI | D39: XLS | E39: Kabel optic AAU | F39: tarikan | G39: 3
B40: E3500375 | C40: MERPATI | D40: XLS | E40: Kabel optic RRU | F40: tarikan | G40: 8
... B48: E3500375 | C48: MERPATI | D48: XLS | E48: Belting kabinet | F48: pcs | G48: 1
B49: R3580695 | C49: 3G_KUPANG KRAJAN | D49: XLS | E49: Antenna sector | F49: pcs | G49: 3 | H49: KCK031874630005B KCK031874630011W KCK03187463000WW
B50: R3580695 | C50: 3G_KUPANG KRAJAN | D50: XLS | E50: RRU 9264 | F50: pcs | G50: 5 | H50: 219645649504 219644276184 219644276183 219645649564 219645642979
...

Sheet LOS Survey
C1: LINK INFORMATION
U2: 14BRS0006 KARANGJUNTI_CM | V2: 14BRS0011 RUNGKANG_TB
C3: Near End | I3: Far End | O3: Result | P3: Remark | T3: Latitude | U3: 6°54'51.5"S | V3: 6°54'58.1"S
A4: Site ID | B4: Site Name | C4: Site ID & Site Name (A) | D4: Longitude (e) | E4: Latitude (s) | F4: Antenna Height (m) | G4: Azimuth (º) | H4: Distance (Km) | I4: Candidate | J4: Site ID & Site Name (B) | K4: Longitude (e) | L4: Latitude (s) | M4: Antenna Height (m) | N4: Azimuth (º) | T4: Longitude | U4: 108°47'39.1"E | V4: 108°48'32.4"E
A5: R1200302 | B5: BANGUN PURBA | C5: SUM-SU-LBP-0054 BANGUN PURBA Relocation | F5: proposed at height 60 | G5: 185 | H5: 8.1 | J5: SUM-SU-SRH-1245 Sei Buaya | K5: 98.8075625 | L5: 3.2984375 | M5: proposed at height 50 | N5: 6 | O5: LOS | P5: Need actual survey | T5: True azimuth (°) | U5: 90 | V5: 15
A6: R1200302 | B6: BANGUN PURBA | C6: SUM-SU-LBP-0054 BANGUN PURBA Relocation | F6: proposed at height 52 | G6: 10.5 | H6: 6.6 | J6: SUM-SU-LBP-0412 Batu Lokong | K6: 98.8301875 | L6: 3.4295625 | M6: proposed at height 55 | N6: 195 | O6: LOS | P6: Need actual survey | T6: Elevation (m) | U6: 12 | V6: 18
A7: R1200302 | B7: BANGUN PURBA | C7: SUM-SU-LBP-0054 BANGUN PURBA Relocation | F7: proposed at height 53 | G7: 10 | H7: 12.9 | J7: SUM-SU-SRH-8224 SF_Pematang Raya 2_COLLECTOR | K7: 98.79774944 | L7: 3.255764722 | M7: proposed at height 55 | N7: 190 | O7: LOS | P7: Need actual survey
A8: E3500158 | B8: PLANDI | C8: 16JMB0118 SUMBER_MULYO_MT | D8: 112.26398 | E8: -7.56379 | F8: proposed at height 43 | G8: 220 | H8: 1.1 | I8: 1 | J8: 16JMB0108 PLANDI_JMB1_EP | K8: 112.257794 | L8: -7.57167 | M8: proposed at height 32 | N8: 40 | O8: LOS
A9: R3350421 | B9: KARANGJUNTI | C9: 14BRS0006 KARANGJUNTI_CM | D9: 108.7942 | E9: -6.9143 | F9: proposed at height 40 | G9: 190 | H9: 1.57 | I9: 1 | J9: 14BRS0004 KUBANGDJERO_TB | K9: 108.79078 | L9: -6.92804 | M9: proposed at height 38 | N9: 20 | O9: LOS
A10: R3350421 | B10: KARANGJUNTI | C10: 14BRS0006 KARANGJUNTI_CM | D10: 108.7942 | E10: -6.9143 | F10: proposed at height 40 | G10: 90 | H10: 1.64 | I10: 2 | J10: 14BRS0011 RUNGKANG_TB | K10: 108.809 | L10: -6.91615 | M10: proposed at height 40 | N10: 280 | O10: LOS
A11: R3350421 | B11: KARANGJUNTI | C11: 14BRS0006 KARANGJUNTI_CM | D11: 108.7942 | E11: -6.9143 | F11: proposed at height 40 | G11: 50 | H11: 2.37 | I11: 3 | J11: 14BRS0013 PEJAGAN3RUNGKANG_AG | K11: 108.81081 | L11: -6.90065 | M11: proposed at height 50 | N11: 230 | O11: LOS
A12: E3200182 | B12: GEULIS_RESORT | C12: E3200182 GEULIS_RESORT | D12: 106.866094 | E12: -6.631617 | F12: Proposed at height 49 | G12: 290 | H12: 3.51 | J12: JAW-JB-BGR-0421 GERBANG CIAWI | K12: 106.835292 | L12: -6.623942 | M12: Existing

Sheet List team
A1: No | B1: Nama | C1: ID KTP | D1: Tanggal Lahir | E1: Task | F1: Province | G1: Jenis Sertif | H1: No Sertif | I1: Contact
A2: 1 | B2: Utut Wahyu Eka | C2: 3175101512870006 | D2: 32126 | E2: Engineer | F2: BALI
A3: 2 | B3: Hoirul Anam | C3: 3509131008950005 | D3: 34921 | E3: Team Leader | F3: BALI | G3: TKPK1 | H3: 12625/TKPK-TK1/XII/2021
A4: 3 | B4: Muhammad Bahtiar | C4: 3501120202880002 | D4: 32175 | E4: Installer | F4: BALI | G4: TKPK1 | H4: 1221181022/N-TKPK1/31/X/2022
A5: 4 | B5: Martono | C5: 3511700407860004 | D5: 31597 | E5: Installer | F5: BALI
A6: 5 | B6: Ardiyanto Lase | C6: 2171121512900000 | D6: 15/12/1990 | E6: Installer | F6: BALI | G6: FA | H6: 00716/020/DSB/P3K/SEPTEMBER/22
A7: 6 | B7: M. Andrian Armeidiana | C7: 3522060205930005 | D7: 34005 | E7: Team Leader | F7: JAKARTA | G7: FA | H7: 00844/024/DSB/P3K/OCTOBER/22
A8: 7 | B8: Bagus Tri Wardani | C8: 3517071608910002 | D8: 16/8/1991 | E8: Installer | F8: JAKARTA | G8: TKPK1 | H8: 0184021122/N-TKPK1/32/XI/2022
A9: 8 | B9: Akhmad Soleh | C9: 3371010708840001 | D9: 7/8/1984 | E9: Installer | F9: JAKARTA
A10: 9 | B10: Akub | C10: 3604161201900001 | D10: 20/1/1990 | E10: Installer | F10: JAKARTA
A11: 10 | B11: Joko Dedoyo Kecil Liyanto | C11: 3315121502970005 | D11: 35476 | E11: Engineer | F11: JAWA TENGAH
A12: 11 | B12: Muhamad Ali Nur S | C12: 3315122911940002 | D12: 34667 | E12: Team Leader | F12: JAWA TENGAH | G12: TKPK1 | H12: 0843281022/N-TKPK1/33/X/2022
A13: 12 | B13: Jimmi Perdana Putra | C13: 3315120408010003 | D13: 36533 | E13: Member | F13: JAWA TENGAH | G13: TKPK1 | H13: 0414200922/N-TKPK1/31/IX/2022
A14: 13 | B14: Hengki Irawan | C14: 3315120107010009 | D14: 36532 | E14: Member | F14: JAWA TENGAH
A15: 14 | B15: Rano Aprilian Werdhana | C15: 3578040604880002 | D15: 32239 | E15: Team Leader | F15: JAWATIMUR | G15: TKPK1 | H15: 0218190522/N-TKPK1/31/V/2022
A16: 15 | B16: Adi Putra | C16: 3516070402920001 | D16: 33638 | E16: Installer | F16: JAWA TIMUR | G16: TKPK1 | H16: 5268/TKPKT-T1-TELKO/X/2021
A17: 16 | B17: Riza Brama Putra | C17: 3578041202860001 | D17: 31455 | E17: Installer | F17: JAWA TIMUR
A18: 17 | B18: Dicky Dermawan | C18: 3578042504020001 | D18: 37371 | E18: Installer | F18: JAWA TIMUR | G18: TKPK1 | H18: 3378/TKPK-TK1-TELKO/X/2020-BT
A19: 18 | B19: Widodo | C19: 3578091606740001 | D19: 16/06/1974 | E19: Installer | F19: JAWA TIMUR | G19: FA | H19: 01129/042/DSB/P3K/DECEMBER/22
A20: 19 | B20: Mohamad Hendra | C20: 5308181905860000 | D20: 19/05/1986 | E20: Team Leader | F20: KALIMANTAN TIMUR
A21: 20 | B21: Brayen Varmandhella | C21: 3506131805990001 | D21: 18/05/1999 | E21: Installer | F21: KALIMANTAN TIMUR | G21: TKPK1 | H21: 0548220722/N-TKPK1/51/VII/2022
A22: 21 | B22: Tri Nurdiansyah | C22: 3216071611950006 | D22: 16/11/1995 | E22: Installer | F22: KALIMANTAN TIMUR | G22: TKPK1 | H22: 22674/TKBT-TK2/X/2020-BT
A23: 22 | B23: Samsudin Bin Arbaa | C23: 5308181007910001 | D23: 33518 | E23: Installer | F23: KALIMANTAN TIMUR
A24: 25 | B24: Sunarji | C24: 3524161003880001 | D24: 31481 | E24: Installer | F24: LAMPUNG | G24: FA | H24: 01128/042/DSB/P3K/DECEMBER/22
A25: 27 | B25: ahmad | C25: 7371091507860007 | D25: 31608 | E25: Team Leader | F25: MALUKU UTARA
A26: 28 | B26: Putut Rahadi | C26: 3578140909680000 | D26: 27958 | E26: Installer | F26: MALUKU UTARA | G26: TKPK1 | H26: 4957/TKPK-TK1-TELKO/X/2021
A27: 29 | B27: Andi Kurniawan | C27: 3328181808890006 | D27: 32738 | E27: Installer | F27: MALUKU UTARA
A28: 30 | B28: Achmad Taufan Ardhitya Nugraha | C28: 3578082603000001 | D28: 36610 | E28: Installer | F28: MALUKU UTARA | G28: TKPK1 | H28: 0559220722/N-TKPK1/35/VII/2022
A29: 31 | B29: Obet Benmetan | C29: 5302072405020001 | D29: 37400 | E29: Engineer | F29: NTT
A30: 32 | B30: Tarman | C30: 3514011709780001 | D30: 28750 | E30: Team Leader | F30: NTT | G30: TKPK1 | H30: 0058011022/N-TKPK1/32/X/2022
A31: 33 | B31: Fredi Septi Arianto | C31: 3517132409880002 | D31: 32410 | E31: Member | F31: NTT | G31: TKPK1 | H31: 4350/TKPK-TK1-TELKO/IV/2021
A32: 34 | B32: Sunardi | C32: 3574030410840005 | D32: 30959 | E32: Member
A33: 35 | B33: ABD. KARIM JOKO WIBOWO | C33: 7306132109790002 | D33: 26563 | E33: Team Leader | F33: PAPUA TENGAH
A34: 36 | B34: MUH. SAMSUNAR S | C34: 7371120702030007 | D34: 36587 | E34: Member | F34: PAPUA TENGAH
A35: 37 | B35: SAPARUDDIN | C35: 7305011002850001 | D35: 31088 | E35: Member | F35: PAPUA TENGAH
A36: 38 | B36: Moch. Ridwan | C36: 3578141006820003 | D36: 30112 | E36: Member | F36: PAPUA TENGAH | G36: TKPK1 | H36: 4960/TKPK-TK1-TELKO/X/2021
A37: 39 | B37: Saddam Husein | C37: 3578071905920001 | D37: 33743 | E37: Member | F37: PAPUA TENGAH | G37: TKPK1 | H37: 4959/TKPK-TK1-TELKO/X/2021
A38: 40 | B38: Moch Haris Islami | C38: 3578060812840002 | D38: 31024 | E38: Team Leader | F38: RIAU | G38: TKPK1 | H38: 5/0783240622/AS.01.04/VI/2022
A39: 41 | B39: Rafsyanjani Akbar | C39: 3215051102870003 | D39: 31819 | E39: Member | F39: RIAU | G39: TKPK1 | H39: 4958/TKPK-TK1-TELKO/X/2021
A40: 42 | B40: Rekli Mustofa | C40: 3374131209790006 | D40: 29110 | E40: Member | F40: RIAU
...

Sheet Email Permit
A1: No | B1: Name | C1: PIC Site | D1: ID KTP | E1: Contact Number | F1: Email Company | G1: Password | H1: Start Account | I1: Expired Account | J1: Validity Account
A2: 1 | B2: Muhamad Darmanto | D2: 3309142707940006 | E2: 087865247367 | F2: darmanto@tunggalsahabat.co.id | H2: 46119 | I2: 46179 | J2: =IF(I2="","",I2-TODAY()) -> -60
A3: =+A2+1 -> 2 | B3: Muchamad Faiz Fahmi | D3: 3325080505030004 | E3: 085643166021 | F3: faizfahmi@tunggalsahabat.co.id | H3: 46119 | I3: =+H3+60 -> 46179 | J3: =IF(I3="","",I3-TODAY()) -> -60
A4: =+A3+1 -> 3 | B4: Arrys Yasir Zulkarnain | D4: 3515111205800002 | E4: 089612377850 | F4: yasir@tunggalsahabat.co.id | H4: 46119 | I4: =+H4+60 -> 46179 | J4: =IF(I4="","",I4-TODAY()) -> -60
A5: =+A4+1 -> 4 | B5: FARIZ MEYER | D5: 3203112212830003 | E5: 08814372949 | F5: fariz@tunggalsahabat.co.id | H5: 46119 | I5: =+H5+60 -> 46179 | J5: =IF(I5="","",I5-TODAY()) -> -60
A6: =+A5+1 -> 5 | B6: TAUFIK HIDAYAT | D6: 3275081809800033 | E6: 081213207645 | F6: taufik@tunggalsahabat.co.id | H6: 46119 | I6: =+H6+60 -> 46179 | J6: =IF(I6="","",I6-TODAY()) -> -60
A7: =+A6+1 -> 6 | B7: Abe Taskura Rizal | D7: 3578020206890006 | E7: 082141021724 | F7: abe.taskurarizal@tunggalsahabat.co.id | H7: 46119 | I7: =+H7+60 -> 46179 | J7: =IF(I7="","",I7-TODAY()) -> -60
A8: =+A7+1 -> 7 | B8: JOKO NURSIO | D8: 3578182109800001 | E8: 087777788432 | F8: joko.nursio@tunggalsahabat.co.id | J8: =IF(I8="","",I8-TODAY())
A9: 8 | B9: Suliswanto | D9: 3316071612950001 | E9: 089670307305 | F9: suliswanto@tunggalsahabat.co.id | G9: &,=U^$rM*k^H
A10: =+A8+1 -> 8 | B10: Ilham Tirta Kawah | D10: 3578052606930002 | E10: 085933744676 | F10: Ilham.tirta@tunggalsahabat.co.id | H10: 46119 | I10: 46179 | J10: =IF(I10="","",I10-TODAY()) -> -60
A11: =+A10+1 -> 9 | B11: Munasirin | C11: Centra Java | D11: 3324012212860001 | E11: +62 812-5666-0163 | F11: munasirin.ext_cj@tunggalsahabat.co.id | G11: w[CatTrQLY7G | J11: =IF(I11="","",I11-TODAY())
A12: =+A11+1 -> 10 | B12: Rano Aprilian Werdhana | C12: East Java | D12: 3578040604880002 | E12: +62 896-7799-6532 | F12: rano.ext_jav@tunggalsahabat.co.id | G12: Pdyp4Pm,$!@X | J12: =IF(I12="","",I12-TODAY())
A13: =+A12+1 -> 11 | B13: Herawan Bin Nasir | C13: Kep. Riau | E13: +62 859-3834-20733 | F13: herawan.ext_sum@tunggalsahabat.co.id | G13: b,kTkZ&n4Db2 | J13: =IF(I13="","",I13-TODAY())
A14: =+A13+1 -> 12 | B14: Sunandar Sandya Ramdhan | C14: Central Kalimantan | D14: 7304032512990002 | E14: +62 823-5732-2405 | F14: sandya.ext_kal@tunggalsahabat.co.id | G14: OrDJNCv?J3oH | J14: =IF(I14="","",I14-TODAY())
A15: =+A14+1 -> 13 | B15: Adi Nugroho | E15: +62 812-3567-0006 | F15: adinugroho.ext@tunggalsahabat.co.id | G15: ~K,yBNDoX&@y | J15: =IF(I15="","",I15-TODAY())
A16: =+A15+1 -> 14 | B16: Andi Wawan | C16: West Java | D16: 3275010107750260 | E16: +62 819-9910-1650 | F16: andiwawan.ext_wj@tunggalsahabat.co.id | G16: wgwYgLGQbl$6 | J16: =IF(I16="","",I16-TODAY())
A17: =+A16+1 -> 15 | B17: Dedi Djunaidi | C17: Sulawesi | D17: 7171032606700001 | E17: +62 81-1412-1707 | F17: djunaidi.ext_sul@tunggalsahabat.co.id | G17: VPZ^J}VD8mWF | J17: =IF(I17="","",I17-TODAY())
A18: =+A17+1 -> 16 | B18: Safar | C18: Sulawesi Tenggara | D18: 7402020511850003 | E18: +62 852-4162-2480 | F18: safar.ext_ken@tunggalsahabat.co.id | G18: &eg?Q5Y2V~ff | J18: =IF(I18="","",I18-TODAY())
A19: =+A18+1 -> 17 | B19: Dwi Raharjo | C19: Jabo | D19: 3304121003890006 | E19: +62 838-4577-1263 | F19: raharjo.ext_jabo@tunggalsahabat.co.id | G19: *5tuQ@s?yw2# | J19: =IF(I19="","",I19-TODAY())
A20: =+A19+1 -> 18 | B20: Rangga Kenanga | C20: Jabo | D20: 3201201409810001 | E20: +62 895-1706-7001 | F20: rangga.kenanga@tunggalsahabat.co.id | G20: 6q5e*8)0UU9z | J20: =IF(I20="","",I20-TODAY())
A21: =+A20+1 -> 19 | B21: Dicky Dermawan | C21: East Java | D21: 3578042504020001 | E21: +62 819-590-886 | F21: dicky.dermawan_ext@tunghalsahabat.co.id | G21: 9@6Y549;*Y26 | J21: =IF(I21="","",I21-TODAY())
A22: =+A21+1 -> 20 | B22: Haslan | C22: Sulawesi Selatan | D22: 7372041010840003 | F22: haslan_ext@tunggalsahabat.co.id | G22: bv#(RWlm~VR= | J22: =IF(I22="","",I22-TODAY())
A23: =+A22+1 -> 21 | B23: Agus Sudarwanto | C23: East Java | D23: 3524131805850002 | F23: agus.sudarwanto_ext@tunggalsahabat.co.id | G23: +}aYEo)0ssT0% | J23: =IF(I23="","",I23-TODAY())
A24: =+A23+1 -> 22 | B24: Muchammad Adhim | C24: East Java | D24: 3515130404860005 | F24: muchammad.adhim_ext@tunggalsahabat.co.id | G24: pTo_[-2v7,{q | J24: =IF(I24="","",I24-TODAY())
A25: =+A24+1 -> 23 | B25: Hoirul Anam | C25: East Java | D25: 3524131805850002 | F25: hoirulanam.ext_ej@tunggalsahabat.co.id | G25: Td7Tj=mN$~t^ | J25: =IF(I25="","",I25-TODAY())
A26: =+A25+1 -> 24 | B26: Bayu Martin Iksanudin | C26: West Java | D26: 3315121209950002 | F26: bayu.martin_ext@tunggalsahabat.co.id | G26: zY$C^lcK47]l | J26: =IF(I26="","",I26-TODAY())
A27: =+A26+1 -> 25 | B27: Arif Moh Riyadi | C27: Central Java | D27: 3315121006860001 | F27: arif.mohriyadi_ext@tunggalsahabat.co.id | G27: Doiw4{hY}veM | J27: =IF(I27="","",I27-TODAY())
A28: =+A27+1 -> 26 | B28: Mubarok | C28: East Java | D28: 3578161408870011 | F28: mubarok_ext@tunggalsahabat.co.id | G28: 2#.ZVXUo;akB | J28: =IF(I28="","",I28-TODAY())
A29: =+A28+1 -> 27 | B29: Yuda | C29: West Java | D29: 3216220112820005 | F29: yuda.ext@tunggalsahabat.co.id | G29: wo&cF!d@olge | J29: =IF(I29="","",I29-TODAY())
A30: =+A29+1 -> 28 | B30: Haris Affandie | C30: Kalimantan | D30: 6471052008800013 | E30: 081258518280 | F30: haris.affandie_ext@tunggalsahabat.co.id | G30: -A_n-a5o#2Ha | J30: =IF(I30="","",I30-TODAY())
A31: =+A30+1 -> 29 | B31: Bambang Sumartono | C31: Central Java | D31: 3374091003740004 | E31: 085742288777 | F31: bambang_ext.cj@tunggalsahabat.co.id | G31: #1F;)ybihtst | J31: =IF(I31="","",I31-TODAY())
A32: =+A31+1 -> 30 | B32: Tri Margiyanto | C32: JAYENGAN | D32: 3311012907830000 | E32: 085332424444 | F32: tri.margiyanto_ext@tunggalsahabat.co.id | G32: QK4rwj]SJ2YF | J32: =IF(I32="","",I32-TODAY())
A33: =+A32+1 -> 31 | B33: Yoricho Bashkara | C33: PEMENANG BARAT | D33: 3275091304950022 | E33: 087845606243 | F33: yoricho.bashkara@tunggal.sahabat.co.id | G33: QJ0mrq3Vy,IN | J33: =IF(I33="","",I33-TODAY())
A34: =+A33+1 -> 32 | B34: Yayat | C34: Kayoon | D34: 3211180401790001 | E34: 083148960851 | F34: yayat_ext@tunggalsahabat.co.id | G34: En4W{a.vOGbc | J34: =IF(I34="","",I34-TODAY())
A35: =+A34+1 -> 33 | B35: Ajang Suprianto | E35: 08813913468 | F35: ajang.suprianto_ext@tunggalsahabat.co.id | G35: }2bt8Cs*O=-p | J35: =IF(I35="","",I35-TODAY())
A36: =+A35+1 -> 34 | B36: Dede Darno | E36: 083112166206 | F36: dede.darno_ext@tunggalsahabat.co.id | G36: r5%AXQTo$&ec | J36: =IF(I36="","",I36-TODAY())
A37: =+A36+1 -> 35 | B37: Edih | E37: 085600237809 | F37: edih_ext@tunggalsahabat.co.id | G37: j%V+3]?sfF.] | J37: =IF(I37="","",I37-TODAY())
A38: =+A37+1 -> 36 | B38: Priatna | C38: Kayoon | D38: 3211130901890002 | E38: 088295614399 | F38: priatna_ext@tunggalsahabat.co.id | G38: f?~.;{n36q#u | J38: =IF(I38="","",I38-TODAY())
A39: =+A38+1 -> 37 | B39: Supriatna | C39: Kayoon | D39: 3211112311740009 | E39: 082286731149 | F39: supriatna_ext@tunggalsahabat.co.id | G39: ,@,WRs)QS(NV | J39: =IF(I39="","",I39-TODAY())
A40: =+A39+1 -> 38 | B40: Wino | C40: Kayoon | D40: 3304141604820004 | E40: 085291104789 | F40: wino_ext@tunggalsahabat.co.id | G40: !?G~9r5=uyaj | J40: =IF(I40="","",I40-TODAY())
...

Sheet SPH
L1: 6826391.4
B2: {=COUNTA(_xlfn.UNIQUE(_xlfn._xlws.FILTER(B4:B973,SUBTOTAL(3,OFFSET(B4,ROW(B4:B973)-ROW(B4),0)))))} -> 1 | C2: {=COUNTA(_xlfn.UNIQUE(_xlfn._xlws.FILTER(C4:C973,SUBTOTAL(3,OFFSET(C4,ROW(C4:C973)-ROW(C4),0)))))} -> 1 | D2: {=COUNTA(_xlfn.UNIQUE(_xlfn._xlws.FILTER(D4:D973,SUBTOTAL(3,OFFSET(D4,ROW(D4:D973)-ROW(D4),0)))))} -> 1 | L2: =+SUBTOTAL(9,L4:L978) -> 6.6794751e+08
A3: No | B3: Account Project | C3: Site ID | D3: Site Name | E3: Create Date | F3: SPH Number | G3: Scope | H3: Description | I3: Qty | J3: UoM | K3: Price | L3: Total | M3: DRM | N3: BAN App | O3: BAN Number | P3: Remark
B4: CMI-RLC-Nasional | C4: E3500300 | D4: DUKUH_KUPANG | E4: 45891 | F4: 006/TSA-SPH-CMI/VIII/2025 | G4: Dismantle Tower | H4: Biaya buat Pagar site keliling 48 m² | I4: 1 | J4: All In | K4: 75000000 | L4: =+I4*K4 -> 75000000 | N4: 45960
B5: CMI-RLC-Nasional | C5: E3500300 | D5: DUKUH_KUPANG | E5: 45891 | F5: 006/TSA-SPH-CMI/VIII/2025 | G5: Dismantle Tower | H5: Management fee pembuatan Pagar | I5: 0.1 | J5: All In | K5: 75000000 | L5: =+I5*K5 -> 7500000 | N5: 45960
B6: CMI-RLC-Nasional | C6: E3500300 | D6: DUKUH_KUPANG | E6: 45891 | F6: 006/TSA-SPH-CMI/VIII/2025 | G6: Dismantle Tower | H6: sewa genset 5 kva | I6: 2 | J6: day | K6: 1200000 | L6: =+I6*K6 -> 2400000 | N6: 45960
B7: CMI-RLC-Nasional | C7: E3500300 | D7: DUKUH_KUPANG | E7: 45891 | F7: 006/TSA-SPH-CMI/VIII/2025 | G7: Dismantle Tower | H7: BBM Genset | I7: 2 | J7: day | K7: 150000 | L7: =+I7*K7 -> 300000 | N7: 45960
B8: CMI-RLC-Nasional | C8: E3500300 | D8: DUKUH_KUPANG | E8: 45891 | F8: 006/TSA-SPH-CMI/VIII/2025 | G8: Dismantle Tower | H8: Operator Genset | I8: 2 | J8: day | K8: 150000 | L8: =+I8*K8 -> 300000 | N8: 45960
B9: CMI-RLC-Nasional | C9: E3500300 | D9: DUKUH_KUPANG | E9: 45891 | F9: 006/TSA-SPH-CMI/VIII/2025 | G9: Relocation Equipment | H9: Kabel AWG 10 XL | I9: 100 | J9: meter | K9: 35000 | L9: =+I9*K9 -> 3500000 | N9: 45960
B10: CMI-RLC-Nasional | C10: E3500300 | D10: DUKUH_KUPANG | E10: 45891 | F10: 006/TSA-SPH-CMI/VIII/2025 | G10: Relocation Equipment | H10: Kabel AWG 6 IOH | I10: 200 | J10: meter | K10: 55000 | L10: =+I10*K10 -> 11000000 | N10: 45960
B11: CMI-RLC-Nasional | C11: E3500300 | D11: DUKUH_KUPANG | E11: 45891 | F11: 006/TSA-SPH-CMI/VIII/2025 | G11: Relocation Equipment | H11: Kabel Feeder 7/8 | I11: 500 | J11: meter | K11: 50000 | L11: =+I11*K11 -> 25000000 | N11: 45960
B12: CMI-RLC-Nasional | C12: E3500300 | D12: DUKUH_KUPANG | E12: 45891 | F12: 006/TSA-SPH-CMI/VIII/2025 | G12: Relocation Equipment | H12: Jumper Feeder | I12: 10 | J12: pcs | K12: 450000 | L12: =+I12*K12 -> 4500000 | N12: 45960
B13: CMI-RLC-Nasional | C13: E3500300 | D13: DUKUH_KUPANG | E13: 45891 | F13: 006/TSA-SPH-CMI/VIII/2025 | G13: Relocation Equipment | H13: Connector Feeder | I13: 20 | J13: pcs | K13: 75000 | L13: =+I13*K13 -> 1500000 | N13: 45960
B14: CMI-RLC-Nasional | C14: E3300285 | D14: JAYENGAN | E14: 45961 | F14: 014/TSA-SPH-CMI/X/2025 | G14: Dismantle Tower | H14: Pembongkaran pondasi ex tower dan bts serta perapian renovasi gedung oleh pihak pemilik lahan | I14: 1 | J14: Ls | K14: 4650000 | L14: =+I14*K14 -> 4650000 | N14: 46028
B15: CMI-RLC-Nasional | C15: E3300285 | D15: JAYENGAN | E15: 45961 | F15: 014/TSA-SPH-CMI/X/2025 | G15: Dismantle Tower | H15: Management Fee | I15: 1 | J15: Ls | K15: 2700000 | L15: =+I15*K15 -> 2700000 | N15: 46028
... B24: CMI-RLC-Nasional | C24: E1200372 | D24: NONGSA_RESORT_1 | E24: 45943 | F24: 007/TSA-SPH-CMI/X/2025 | G24: Relocation Equipment | H24: Tiket Pesawat Batam - Jakarta | I24: 4 | J24: Person | K24: 1000000 | L24: =+I24*K24 -> 4000000 | N24: 46000
B25: CMI-RLC-Nasional | C25: E3600214 | D25: SUPERMAL | E25: 45959 | F25: 013/TSA-SPH-CMI/X/2025 | G25: Dismantle Tower | H25: Management Fee | I25: 1 | J25: Ls | K25: 2700000 | L25: =+I25*K25 -> 2700000
B26: CMI-RLC-Nasional | C26: E3600214 | D26: SUPERMAL | E26: 45959 | F26: 013/TSA-SPH-CMI/X/2025 | G26: Relocation Equipment | H26: Pembelian Rack Outdoor include delivery | I26: 2 | J26: unit | K26: 7000000 | L26: =+I26*K26 -> 14000000
B27: CMI-RLC-Nasional | C27: E3600214 | D27: SUPERMAL | E27: 45959 | F27: 013/TSA-SPH-CMI/X/2025 | G27: Relocation Equipment | H27: Pembelian Kabel AWG 10 | I27: 175 | J27: meter | K27: 35000 | L27: =+I27*K27 -> 6125000
B28: CMI-RLC-Nasional | C28: E3600214 | D28: SUPERMAL | E28: 45959 | F28: 013/TSA-SPH-CMI/X/2025 | G28: Relocation Equipment | H28: Pembelian opctic CPRI 70 meter | I28: 7 | J28: pcs | K28: 250000 | L28: =+I28*K28 -> 1750000
B29: CMI-RLC-Nasional | C29: E3600214 | D29: SUPERMAL | E29: 45959 | F29: 013/TSA-SPH-CMI/X/2025 | G29: Relocation Equipment | H29: Pembelian Kabel coax RG8 | I29: 100 | J29: meter | K29: 15000 | L29: =+I29*K29 -> 1500000
B30: CMI-RLC-Nasional | C30: E1200351 | D30: DANAGRAHA_BUILDING1 / DANA GRAHA | E30: 45965 | F30: 001/TSA-SPH-CMI/XI/2025 | G30: Dismantle Tower | H30: Scrap Lokal onsite | I30: 1488.6 | J30: Kg | K30: -1500 | L30: =+I30*K30 -> -2232900 | N30: 46365
B31: CMI-RLC-Nasional | C31: E1200351 | D31: DANAGRAHA_BUILDING1 / DANA GRAHA | E31: 45965 | F31: 001/TSA-SPH-CMI/XI/2025 | G31: Dismantle Tower | H31: Management Fee | I31: 1 | J31: Ls | K31: 2700000 | L31: =+I31*K31 -> 2700000 | N31: 46365
B32: CMI-RLC-Nasional | C32: E1200351 | D32: DANAGRAHA_BUILDING1 / DANA GRAHA | E32: 45965 | F32: 001/TSA-SPH-CMI/XI/2025 | G32: Dismantle Tower | H32: Membrane bakar merk fosroc 14 meter (2 rol x 10 m) | I32: 2 | J32: roll | K32: 1700000 | L32: =+I32*K32 -> 3400000 | N32: 46365
B33: CMI-RLC-Nasional | C33: E1200351 | D33: DANAGRAHA_BUILDING1 / DANA GRAHA | E33: 45965 | F33: 001/TSA-SPH-CMI/XI/2025 | G33: Dismantle Tower | H33: Tukang pasang membrane bakar | I33: 14 | J33: meter | K33: 80000 | L33: =+I33*K33 -> 1120000 | N33: 46365
B34: CMI-RLC-Nasional | C34: E1200351 | D34: DANAGRAHA_BUILDING1 / DANA GRAHA | E34: 45965 | F34: 001/TSA-SPH-CMI/XI/2025 | G34: Dismantle Tower | H34: Ongkos unloading material ke lt 6 | I34: 1 | J34: Ls | K34: 300000 | L34: =+I34*K34 -> 300000 | N34: 46365
B35: CMI-RLC-Nasional | C35: E1200351 | D35: DANAGRAHA_BUILDING1 / DANA GRAHA | E35: 45965 | F35: 001/TSA-SPH-CMI/XI/2025 | G35: Dismantle Tower | H35: PB-CME-266 Plester Aci | I35: 22 | J35: M² | K35: 56000 | L35: =+I35*K35 -> 1232000 | N35: 46365
B36: CMI-RLC-Nasional | C36: E1200351 | D36: DANAGRAHA_BUILDING1 / DANA GRAHA | E36: 45965 | F36: 001/TSA-SPH-CMI/XI/2025 | G36: Dismantle Tower | H36: PB-CME-266 Waterproofing (SikaTop 107 Seal) | I36: 22 | J36: M² | K36: 44000 | L36: =+I36*K36 -> 968000 | N36: 46365
B37: CMI-RLC-Nasional | C37: E1200351 | D37: DANAGRAHA_BUILDING1 / DANA GRAHA | E37: 45965 | F37: 001/TSA-SPH-CMI/XI/2025 | G37: Dismantle Tower | H37: PB-CME-271 Pengecatan | I37: 29 | J37: M² | K37: 64000 | L37: =+I37*K37 -> 1856000 | N37: 46365
B38: CMI-RLC-Nasional | C38: R5100062 | D38: SMPK_THOMAS_AQUINO | E38: 45939 | F38: 006/TSA-SPH-CMI/X/2025 | G38: Dismantle Tower | H38: Project Management fee | I38: 1 | J38: Ls | K38: 2700000 | L38: =+I38*K38 -> 2700000 | N38: 45999
B39: CMI-RLC-Nasional | C39: R5100062 | D39: SMPK_THOMAS_AQUINO | E39: 45939 | F39: 006/TSA-SPH-CMI/X/2025 | G39: Dismantle Tower | H39: Delivery material scrap | I39: 1193.68 | J39: Kg | K39: 1800 | L39: =+I39*K39 -> 2148624 | N39: 45999
B40: CMI-RLC-Nasional | C40: R5100062 | D40: SMPK_THOMAS_AQUINO | E40: 45939 | F40: 006/TSA-SPH-CMI/X/2025 | G40: Dismantle Tower | H40: Biaya Langsir roaster dari site ke WH TSA Surabaya | I40: 1 | J40: Ls | K40: 6000000 | L40: =+I40*K40 -> 6000000 | N40: 45999
B41: CMI-RLC-Nasional | C41: E6400049 | D41: WADUK MANGGAR | E41: 46002 | F41: 001/TSA-SPH-CMI/XII/2025 | G41: Dismantle Tower | H41: Ticket Pesawat Semarang to Balikpapan | I41: 5 | J41: orang | K41: 1800000 | L41: =+I41*K41 -> 9000000 | N41: 46028
... B54: CMI-RLC-Nasional | C54: R6300038 | D54: TRANS KALIMANTAN | E54: 46059 | F54: 002/TSA-SPH-CMI/II/2026 | G54: Relocation Equipment | H54: Cable Power RRU Awg 2x10 XLS | I54: 30 | J54: meter | K54: 35000 | L54: =+I54*K54 -> 1050000 | N54: 46135
B55: CMI-RLC-Nasional | C55: E1200343 | D55: TEMIANG_BATAM / BUKIT MATA KUCING 2 | E55: 46020 | F55: 009/TSA-SPH-CMI/XI/2025 | G55: Dismantle Tower | I55: 8236.656 | J55: Kg | K55: -1500 | L55: =+I55*K55 -> -12354984 | N55: 46049
B56: CMI-RLC-Nasional | C56: E1200343 | D56: TEMIANG_BATAM / BUKIT MATA KUCING 2 | E56: 46020 | F56: 009/TSA-SPH-CMI/XI/2025 | G56: Dismantle Tower | H56: Project Management fee | I56: 1 | J56: Ls | K56: 2700000 | L56: =+I56*K56 -> 2700000 | N56: 46049
B57: CMI-RLC-Nasional | C57: E1200343 | D57: TEMIANG_BATAM / BUKIT MATA KUCING 2 | E57: 46020 | F57: 009/TSA-SPH-CMI/XI/2025 | G57: Relocation Equipment | H57: Pembelian kabel twisted 2 x 16 (70m x 3tarikan) | I57: 210 | J57: M | K57: 45000 | L57: =+I57*K57 -> 9450000 | N57: 46049
B58: CMI-RLC-Nasional | C58: E1200343 | D58: TEMIANG_BATAM / BUKIT MATA KUCING 2 | E58: 46020 | F58: 009/TSA-SPH-CMI/XI/2025 | G58: Relocation Equipment | H58: Pembelian optic 100m x 3tarikan | I58: 300 | J58: M | K58: 10000 | L58: =+I58*K58 -> 3000000 | N58: 46049
B59: CMI-RLC-Nasional | C59: R3100450 | D59: KEBON SIRIH | E59: 46014 | F59: 004/TSA-SPH-CMI/XII/2025 | G59: Relocation Equipment | H59: Management Fee | I59: 1 | J59: Ls | K59: 2700000 | L59: =+I59*K59 -> 2700000 | N59: 46050
B60: CMI-RLC-Nasional | C60: R3100450 | D60: KEBON SIRIH | E60: 46014 | F60: 004/TSA-SPH-CMI/XII/2025 | G60: Relocation Equipment | H60: Jasa Kontraktor / AKLI | I60: 1 | J60: Ls | K60: 3300000 | L60: =+I60*K60 -> 3300000 | N60: 46050
...

Sheet oret2
D3: Site ID | E3: Site Name | F3: Tower Provider | G3: LATITUDE | H3: LONGITUDE | I3: Height proposed | J3: Azimuth
C4: Near End (Site Acceptor) | D4: JAW-JB-KNG-1359 | E4: JAPARA KUNINGAN | F4: EMA | G4: -6.89649 | H4: 108.51681 | I4: 44
C5: Far End | D5: JAW-JB-KNG-1353 | E5: KUNINGAN BANGUN | F5: DMT | G5: -6.88686 | H5: 108.502806 | I5: existing
D7: E3200649 | E7: JAPARA

Sheet Update Boram
A1: Update BORAM
R2: ID Pelanggan PLN | S2: Nama Pelanggan PLN | T2: Nama Site | U2: Alamat | V2: Keterangan
A3: No | B3: Site ID CMI | C3: Site Name CMI | D3: Tenant | E3: Site ID Tenant | F3: Site Name Tenant | G3: ID Pel | H3: Daya (VA) | I3: SPBR Submit CMI | J3: SPBR Release | K3: SPBR Submit PLN | L3: BA Boram | M3: Progress | N3: Remark | O3: BOT PLN | R3: 152001107489 | S3: PT. INDOSAT | T3: PINTU4_MUKA_KUNING_EP | U3: JL. TANJUNG RAYA , MUKA KUNING
A4: 1 | B4: R35780005 | C4: WONOKESUMO | D4: IOH | E4: 16SBY0363 | F4: WONOSARILOR_CM | G4: 511040607208 | H4: 10600 | I4: 46125 | L4: 45596 | M4: =+IF(L4<>"","Done Boram",IF(K4<>"","SPBR submit to PLN",IF(J4<>"","SPBR Release",IF(I4<>"","Submit App SPBR","")))) -> Done Boram | N4: IOH tidak mengeluarkan SPBR karena id pel tersebut sudah boram
A5: 2 | B5: R35780005 | C5: WONOKESUMO | D5: TSEL | E5: SBY098 | F5: PEGIRIANCMI | G5: 511040502273 | H5: 10600 | K5: 46125 | L5: 46136 | M5: =+IF(L5<>"","Done Boram",IF(K5<>"","SPBR submit to PLN",IF(J5<>"","SPBR Release",IF(I5<>"","Submit App SPBR","")))) -> Done Boram | N5: SPBR edit sendiri
A6: 3 | B6: E3300061 | C6: RSMARGONO | D6: IOH | E6: 14PWT0167 | F6: RSMARGONO_EP | G6: 522011266252 | I6: 45721 | J6: 45804 | K6: 45805 | L6: 45957 | M6: =+IF(L6<>"","Done Boram",IF(K6<>"","SPBR submit to PLN",IF(J6<>"","SPBR Release",IF(I6<>"","Submit App SPBR","")))) -> Done Boram
A7: 4 | B7: E6400044 | C7: MARKONI | D7: IOH | E7: 22BPP0085 | F7: MARKONI_EP | G7: 232000283760 | I7: 45888 | J7: 45894 | K7: 45895 | L7: 45922 | M7: =+IF(L7<>"","Done Boram",IF(K7<>"","SPBR submit to PLN",IF(J7<>"","SPBR Release",IF(I7<>"","Submit App SPBR","")))) -> Done Boram
A8: 5 | B8: R3350400 | C8: SUMBER LAWANG | D8: XLS | E8: JAW-JT-SGN-1855 | F8: SUMBER LAWANG | G8: 520591331135 | I8: 45844 | J8: 45845 | K8: 45846 | L8: 45858 | M8: =+IF(L8<>"","Done Boram",IF(K8<>"","SPBR submit to PLN",IF(J8<>"","SPBR Release",IF(I8<>"","Submit App SPBR","")))) -> Done Boram
A9: 6 | B9: E8200008 | C9: JAILOLO | D9: IOH | E9: 32HBR0001 | F9: JAILOLO_EP | G9: 412500929541 | I9: 46014 | J9: 46029 | K9: 46029 | L9: 46072 | M9: =+IF(L9<>"","Done Boram",IF(K9<>"","SPBR submit to PLN",IF(J9<>"","SPBR Release",IF(I9<>"","Submit App SPBR","")))) -> Done Boram
A10: 7 | B10: R5100120 | C10: PANTAI PANDAWA | D10: IOH | E10: 17DPR0188 | F10: PANTAIPANDAWA_CM | G10: 551201457578 | I10: 45802 | J10: 45803 | K10: 45804 | L10: 45826 | M10: =+IF(L10<>"","Done Boram",IF(K10<>"","SPBR submit to PLN",IF(J10<>"","SPBR Release",IF(I10<>"","Submit App SPBR","")))) -> Done Boram
A11: 8 | B11: R3580411 | C11: PEGANTENAN | D11: XLS | E11: JAW-JI-PMK-2000 | F11: PEGANTENAN PAMEKASAN | G11: 517800793803 | I11: 46002 | J11: 46008 | K11: 46008 | L11: 46013 | M11: =+IF(L11<>"","Done Boram",IF(K11<>"","SPBR submit to PLN",IF(J11<>"","SPBR Release",IF(I11<>"","Submit App SPBR","")))) -> Done Boram
A12: 9 | B12: E3500148 | C12: KEDUNGPRING | D12: IOH | E12: 16LMG0033 | F12: KEDUNGPRING_EP | G12: 518041036694 | I12: 45922 | J12: 45922 | K12: 45923 | L12: 45948 | M12: =+IF(L12<>"","Done Boram",IF(K12<>"","SPBR submit to PLN",IF(J12<>"","SPBR Release",IF(I12<>"","Submit App SPBR","")))) -> Done Boram
A13: 10 | B13: E3500148 | C13: KEDUNGPRING | D13: XLS | E13: JAW-JI-LMG-4290 | F13: KEDUNGPRING TLANAK | G13: 518041755248 | I13: 45921 | J13: 45922 | K13: 45923 | L13: 45940 | M13: =+IF(L13<>"","Done Boram",IF(K13<>"","SPBR submit to PLN",IF(J13<>"","SPBR Release",IF(I13<>"","Submit App SPBR","")))) -> Done Boram
A14: 11 | B14: R6300019 | C14: JL. KELAPA BJM | D14: XLS | E14: KAL-KS-BJM-0197 | F14: JL. KELAPA BJM | G14: 221103103075 | I14: 46153 | J14: 46153 | K14: 46153 | L14: 46164 | M14: =+IF(L14<>"","Done Boram",IF(K14<>"","SPBR submit to PLN",IF(J14<>"","SPBR Release",IF(I14<>"","Submit App SPBR","")))) -> Done Boram | N14: 19.05.26 Boram done
A15: 12 | B15: R6300019 | C15: JL. KELAPA BJM | D15: TSEL | E15: BJM179 | F15: JL. KELAPA BJM | G15: 221103114978 | H15: 10600 | I15: 46153 | J15: 46175 | K15: 46175 | L15: 46206 | M15: =+IF(L15<>"","Done Boram",IF(K15<>"","SPBR submit to PLN",IF(J15<>"","SPBR Release",IF(I15<>"","Submit App SPBR","")))) -> Done Boram
A16: 13 | B16: E5100119 | C16: NUSALEMBONGAN | D16: IOH | E16: 17SPR0033 | F16: NUSALEMBONGAN_EP | G16: 551320015922 | I16: 45929 | J16: 45931 | K16: 45935 | L16: 45940 | M16: =+IF(L16<>"","Done Boram",IF(K16<>"","SPBR submit to PLN",IF(J16<>"","SPBR Release",IF(I16<>"","Submit App SPBR","")))) -> Done Boram
A17: 14 | B17: R3350113 | C17: PLIKEN | D17: IOH | E17: 14PWT0194 | F17: PLIKEN_CM | G17: 522020867980 | M17: =+IF(L17<>"","Done Boram",IF(K17<>"","SPBR submit to PLN",IF(J17<>"","SPBR Release",IF(I17<>"","Submit App SPBR",""))))
A18: 15 | B18: R3350113 | C18: PLIKEN | D18: TSEL | G18: 522020914363 | H18: 7700 | M18: =+IF(L18<>"","Done Boram",IF(K18<>"","SPBR submit to PLN",IF(J18<>"","SPBR Release",IF(I18<>"","Submit App SPBR",""))))
A19: 16 | B19: E1200347 | C19: JODOH | D19: IOH | E19: 05BTM0110 | F19: JODOH_EP | G19: 151001044556 | I19: 45936 | J19: 45930 | K19: 45931 | L19: 45957 | M19: =+IF(L19<>"","Done Boram",IF(K19<>"","SPBR submit to PLN",IF(J19<>"","SPBR Release",IF(I19<>"","Submit App SPBR","")))) -> Done Boram
A20: 17 | B20: R6300038 | C20: TRANS KALIMANTAN | D20: IOH | E20: 23MRB0023 | F20: TRANSKALIMANTAN_CM | G20: 221500493526 | H20: 5500 | I20: 46030 | J20: 46030 | K20: 46041 | L20: 46042 | M20: =+IF(L20<>"","Done Boram",IF(K20<>"","SPBR submit to PLN",IF(J20<>"","SPBR Release",IF(I20<>"","Submit App SPBR","")))) -> Done Boram
A21: 18 | B21: R6300038 | C21: TRANS KALIMANTAN | D21: XLS | E21: KAL-KS-MRH-0386 | F21: TRANS KALIMANTAN | G21: 221500137257 | H21: 13200 | I21: 46030 | J21: 46030 | K21: 46041 | L21: 46042 | M21: =+IF(L21<>"","Done Boram",IF(K21<>"","SPBR submit to PLN",IF(J21<>"","SPBR Release",IF(I21<>"","Submit App SPBR","")))) -> Done Boram
A22: 19 | B22: E1200343 | C22: TEMIANG_BATAM / BUKIT MATA KUCING 2 | D22: IOH | E22: 05BTM0074 | F22: TEMIANG_BATAM_EP | G22: 152001110528 | H22: 13200 | I22: 45996 | J22: 46001 | K22: 46001 | L22: 46010 | M22: =+IF(L22<>"","Done Boram",IF(K22<>"","SPBR submit to PLN",IF(J22<>"","SPBR Release",IF(I22<>"","Submit App SPBR","")))) -> Done Boram
A23: 20 | B23: E1200343 | C23: TEMIANG_BATAM / BUKIT MATA KUCING 2 | D23: XLS | E23: SUM-KR-BTM-0604 | F23: BULIANG | G23: 152002075724 | H23: 6600 | I23: 45996 | J23: 46001 | K23: 46001 | L23: 46010 | M23: =+IF(L23<>"","Done Boram",IF(K23<>"","SPBR submit to PLN",IF(J23<>"","SPBR Release",IF(I23<>"","Submit App SPBR","")))) -> Done Boram
A24: 21 | B24: E1200343 | C24: TEMIANG_BATAM / BUKIT MATA KUCING 2 | D24: TSEL | E24: BTM147 | F24: TEMIANG_BATAM BUKIT MATA KUCING 2 | G24: 152001757921 | H24: 10600 | I24: 45996 | J24: 46006 | K24: 46006 | L24: 46010 | M24: =+IF(L24<>"","Done Boram",IF(K24<>"","SPBR submit to PLN",IF(J24<>"","SPBR Release",IF(I24<>"","Submit App SPBR","")))) -> Done Boram
A25: 22 | B25: E3600061 | C25: PARUNGSARI | D25: IOH | E25: 11RKB0143 | F25: PARUNGSARI_RKB1_EP | G25: 539211120671 | I25: 45871 | J25: 45877 | K25: 45878 | L25: 45926 | M25: =+IF(L25<>"","Done Boram",IF(K25<>"","SPBR submit to PLN",IF(J25<>"","SPBR Release",IF(I25<>"","Submit App SPBR","")))) -> Done Boram
A26: 23 | B26: E3600061 | C26: PARUNGSARI | D26: XLS | E26: NJKT_1717 | F26: PARUNGSARI | G26: 562100172529 | I26: 45935 | J26: 45936 | K26: 45937 | L26: 45941 | M26: =+IF(L26<>"","Done Boram",IF(K26<>"","SPBR submit to PLN",IF(J26<>"","SPBR Release",IF(I26<>"","Submit App SPBR","")))) -> Done Boram
A27: 24 | B27: E3600061 | C27: PARUNGSARI | D27: TSEL | G27: 562101444860 | I27: 45904 | J27: 45974 | K27: 45974 | L27: 45982 | M27: =+IF(L27<>"","Done Boram",IF(K27<>"","SPBR submit to PLN",IF(J27<>"","SPBR Release",IF(I27<>"","Submit App SPBR","")))) -> Done Boram
A28: 25 | B28: E3200644 | C28: JALAKSANA | D28: IOH | E28: 13KNG0046 | F28: JALAKSANA_EP | G28: 533710563089 | I28: 45975 | J28: 45989 | K28: 45989 | L28: No Boram | M28: =+IF(L28<>"","Done Boram",IF(K28<>"","SPBR submit to PLN",IF(J28<>"","SPBR Release",IF(I28<>"","Submit App SPBR","")))) -> Done Boram
A29: 26 | B29: E3200269 | C29: CILEUNGSIKIDUL | D29: IOH | E29: 13CBN1024 | F29: CIELUNGSIKIDUL_EP | G29: 538654954208 | H29: 23000 | I29: 46120 | J29: 46128 | K29: 46129 | L29: 46133 | M29: =+IF(L29<>"","Done Boram",IF(K29<>"","SPBR submit to PLN",IF(J29<>"","SPBR Release",IF(I29<>"","Submit App SPBR","")))) -> Done Boram
A30: 27 | B30: E3200644 | C30: JALAKSANA | D30: XLS | E30: ZCRB_4188 | F30: JALAKSANA | G30: 533711051862 | I30: 45975 | J30: 45988 | K30: 45988 | L30: 46000 | M30: =+IF(L30<>"","Done Boram",IF(K30<>"","SPBR submit to PLN",IF(J30<>"","SPBR Release",IF(I30<>"","Submit App SPBR","")))) -> Done Boram
A31: 28 | B31: E3200269 | C31: CILEUNGSIKIDUL | D31: XLS | E31: NBGR_0125 | F31: CILEUNGSIKIDUL | G31: 538655662867 | H31: 10600 | I31: 46120 | J31: 46127 | K31: 46127 | L31: 46133 | M31: =+IF(L31<>"","Done Boram",IF(K31<>"","SPBR submit to PLN",IF(J31<>"","SPBR Release",IF(I31<>"","Submit App SPBR","")))) -> Done Boram
A32: 29 | B32: E3500300 | C32: DUKUH_KUPANG | D32: IOH | E32: 16SBY0152 | F32: DUKUH_KUPANG_EP | G32: 511413067240 | I32: 45869 | J32: 45869 | K32: 45870 | L32: 45883 | M32: =+IF(L32<>"","Done Boram",IF(K32<>"","SPBR submit to PLN",IF(J32<>"","SPBR Release",IF(I32<>"","Submit App SPBR","")))) -> Done Boram
A33: 30 | B33: E3500300 | C33: DUKUH_KUPANG | D33: XLS | E33: JAW-JI-SBY-2359 | F33: PUTAT GEDE | G33: 511413182597 | I33: 45869 | J33: 45870 | K33: 45871 | L33: 45878 | M33: =+IF(L33<>"","Done Boram",IF(K33<>"","SPBR submit to PLN",IF(J33<>"","SPBR Release",IF(I33<>"","Submit App SPBR","")))) -> Done Boram
A34: 31 | B34: E3300323 | C34: WIROSARI | D34: IOH | E34: 14GRO0118 | F34: WIROSARI_EP | G34: 523073092633 | I34: 45881 | M34: =+IF(L34<>"","Done Boram",IF(K34<>"","SPBR submit to PLN",IF(J34<>"","SPBR Release",IF(I34<>"","Submit App SPBR","")))) -> Submit App SPBR
A35: 32 | B35: E3200297 | C35: CILOTO | D35: IOH | E35: 13CJR0017 | F35: CILOTO_EP | G35: 536712081435 | M35: =+IF(L35<>"","Done Boram",IF(K35<>"","SPBR submit to PLN",IF(J35<>"","SPBR Release",IF(I35<>"","Submit App SPBR",""))))
A36: 33 | B36: E3600042 | C36: TOL_CILEGON_SERANG | D36: IOH | E36: 11CLG0103 | F36: TOL_CLGN_SRANG_EP | G36: 539411151940 | I36: 45915 | J36: 45915 | K36: 45947 | L36: 45957 | M36: =+IF(L36<>"","Done Boram",IF(K36<>"","SPBR submit to PLN",IF(J36<>"","SPBR Release",IF(I36<>"","Submit App SPBR","")))) -> Done Boram
A37: 34 | B37: E3600042 | C37: TOL_CILEGON_SERANG | D37: XLS | E37: JAW-BT-SRG-1198 | F37: BOJONEGARA_SERDANG | G37: 561200596663 | I37: 45931 | J37: 45932 | K37: 45933 | L37: 45957 | M37: =+IF(L37<>"","Done Boram",IF(K37<>"","SPBR submit to PLN",IF(J37<>"","SPBR Release",IF(I37<>"","Submit App SPBR","")))) -> Done Boram
A38: 35 | B38: E3600042 | C38: TOL_CILEGON_SERANG | D38: TSEL | G38: 539411611457 | I38: 45908 | J38: 45974 | K38: 45974 | L38: 45985 | M38: =+IF(L38<>"","Done Boram",IF(K38<>"","SPBR submit to PLN",IF(J38<>"","SPBR Release",IF(I38<>"","Submit App SPBR","")))) -> Done Boram
A39: 36 | B39: E3100485 | C39: PEDONGKELAN | D39: IOH | E39: 12JKU0476 | F39: PEDONGKELAN_EP | G39: 545200594263 | I39: 46132 | J39: 46146 | M39: =+IF(L39<>"","Done Boram",IF(K39<>"","SPBR submit to PLN",IF(J39<>"","SPBR Release",IF(I39<>"","Submit App SPBR","")))) -> SPBR Release | N39: waiting penyambungan inbuilding di new site
A40: 37 | B40: E3100485 | C40: PEDONGKELAN | D40: TSEL | E40: JUX617 | F40: MEDAN MARUNDA | G40: 545303131129 | I40: 46132 | J40: 46146 | M40: =+IF(L40<>"","Done Boram",IF(K40<>"","SPBR submit to PLN",IF(J40<>"","SPBR Release",IF(I40<>"","Submit App SPBR","")))) -> SPBR Release | N40: waiting penyambungan inbuilding di new site
...

Sheet CMI-RLC-Nasional
A1: Plan
A2: OG
A3: Pending | G3: {=COUNTA(_xlfn.UNIQUE(_xlfn._xlws.FILTER(G6:G995,SUBTOTAL(3,OFFSET(G6,ROW(G6:G995)-ROW(G6),0)))))} -> 1 | I3: =+SUBTOTAL(3,I6:I1002) -> 356 | AH3: =+SUBTOTAL(3,AH6:AH1002) -> 61 | BK3: =+SUBTOTAL(3,BK6:BK1002) -> 152 | BP3: =SUBTOTAL(3,BP6:BP296) -> 291
A4: Prayudi | W4: Aghnia | AD4: Prayudi | AQ4: Prayudi | BF4: Prabowo | BP4: Prayudi | CE4: New Site / FE MW
A5: NO | B5: Vendor Code | C5: Project Code | D5: Scope Of Area | E5: Unique ID | F5: Assignment | G5: Site ID Old | H5: Site ID New | I5: Site Name | J5: Zone | K5: Entity | L5: Provinsi | M5: Kota/Kabupaten | N5: Site Address | O5: LATITUDE | P5: LONGITUDE | Q5: Tower Weight - Original (kg) | R5: Tower Height (Eng) (m) | S5: Tenant | T5: Site Type | U5: Tower Type | V5: SOW Detail | W5: PIC | X5: Kontak | Y5: SOW Permit | Z5: Start | AA5: Expired | AB5: Validitas Permit | AC5: Remark Permit | AD5: Survey | AE5: Survey Report Submit | AF5: End Lease / Drop | AG5: RFD Approved | AH5: Dismantle Perangkat | AI5: Dismantle CME | AJ5: Inbound | AK5: Install | AL5: OA/RFS | AM5: ATP Approve MS | AN5: BAST | AO5: Update Progress | AP5: Remark Progress | AQ5: 1st BOQ Submit | AR5: 1st BOQ Pass TI | AS5: Engineering Structural Manager App | AT5: SPH 1 / BAN 1 App | AU5: Upload 1st BOQ & BAN Isaac | AV5: App 1st BOQ & BAN Isaac | AW5: 1st BOQ | AX5: 2nd BOQ Submit | AY5: 2nd BOQ Pass TI | AZ5: Engineering Structural Manager App | BA5: SPH 2 / BAN 2 App | BB5: Upload 2nd BOQ & BAN Isaac | BC5: App 2nd BOQ & BAN Isaac | BD5: 2nd BOQ | BE5: Remark BOQ | BF5: HSE Plan & JSA Submit | BG5: Isaac HSE Plan & JSA App | BH5: JSA Doc No. | BI5: SWP Submit | BJ5: SWP App | BK5: SWP Doc No | BL5: HSE & JSA | BM5: SWP | BN5: BA Dism / BA OA / BAST Submit | BO5: BA Dism / BA OA / BAST App | BP5: SOW | BQ5: PO Number | BR5: PO Release | BS5: Aging PO | BT5: PO Variation 1 | BU5: PO Variation 1 Release | BV5: Aging PO Variation 1 | BW5: PO Variation 2 | BX5: PO Variation 2 Release | BY5: Aging PO Variation 2 | BZ5: Blocking Issue | CA5: PIC Responsible | CB5: Company | CC5: Target Submit Date | CE5: Site ID | CF5: Site Name | CG5: LATITUDE | CH5: LONGITUDE | CI5: CR IOH | CJ5: XLWO | CK5: CRQ Tsel | CL5: Remark Reloc
A6: 1 | B6: CMI | C6: RLC | D6: Nasional | E6: =+_xlfn.CONCAT(G6,"-",B6,"_",C6,"_",_xlfn.XLOOKUP(BP6,Account!M:M,Account!N:N)) -> #NAME? | F6: 45670 | G6: E3300061 | H6: ID-JT-05773 | I6: RSMARGONO | J6: 11 | K6: EMA | L6: JAWA TENGAH | M6: Kab. Banyumas | N6: KOMPLEK RS. MARGONO JL. JEND. SUDIRMAN PURWOKERTO | O6: -7.43475 | P6: 109.2674 | Q6: 13067.712 | R6: 55 | S6: IOH (hwei) | T6: Greenfield | U6: SST 4 Legs | V6: Dismantle Tower | W6: Joko Dedoyo Kecil Liyanto | X6: 87861095209 | Y6: Dismantle | Z6: 45713 | AA6: 45720 | AB6: =IF(AA6="ds","Submit",IF(AA6="","NY Submit",IF(AA6<TODAY(),"Expired",IFERROR(DATEDIF(TODAY(),AA6,"d"),"")))) -> Expired | AD6: 45681 | AE6: 45686 | AG6: 45716 | AI6: 45722 | AN6: 45727 | AO6: =+IF(AN6<>"","BAST",IF(AI6<>"","Dismantle",IF(AG6<>"","RFD App",IF(AF6="Drop","Drop",IF(AE6<>"","Survey Report",IF(AD6<>"","Survey","NY Survey")))))) -> BAST | AQ6: 45719 | AR6: 45719 | AS6: 45719 | AT6: 45765 | AU6: 45735 | AV6: 45735 | AW6: =+IF(AV6<>"","1st BOQ App on ISAAC",IF(AU6<>"","Upload 1st BOQ & BAN Isaac",IF(AT6="DRM","need DRM",IF(AT6<>"","BAN App",IF(AR6<>"","1st BOQ Pass TI",IF(AS6<>"","Engineering Structural Manager App",IF(AQ6<>"","1st BOQ Submit","NY Submit"))))))) -> 1st BOQ App on ISAAC | BD6: =+IF(BC6<>"","2nd BOQ App on ISAAC",IF(BB6<>"","Upload 2nd BOQ & BAN Isaac",IF(BA6="DRM","need DRM",IF(BA6<>"","BAN App",IF(AZ6<>"","Engineering Structural Manager App",IF(AY6<>"","2nd BOQ Pass TI",IF(AX6<>"","2nd BOQ Submit","NY Submit"))))))) -> NY Submit | BF6: 45689 | BG6: 45695 | BH6: JSA No.02/TSA/HSE/02/2025 | BI6: 45689 | BJ6: 45695 | BK6: SWP-HSE-09 | BL6: =+IF(BG6<>"","Approved",IF(BF6<>"","Submit","NY Submit")) -> Approved | BM6: =+IF(BJ6<>"","Approved",IF(BI6<>"","Submit","NY Submit")) -> Approved | BN6: 45727 | BO6: 45727 | BP6: Dismantle Tower | BQ6: EMAPO25-000807 | BR6: 45791 | BS6: =IF(AO6="Drop", "Drop", IF(ISBLANK(AV6), 0, IF(ISBLANK(BR6), DATEDIF(AV6,TODAY(),"d"), DATEDIF(AV6,BR6,"d") ) ) ) -> 56 | BV6: =IF(AO6="Drop", "Drop", IF(ISBLANK(BC6), 0, IF(ISBLANK(BU6), DATEDIF(BC6,TODAY(),"d"), DATEDIF(BC6,BU6,"d") ) ) ) -> 0 | BZ6: Complete | CE6: ID-JT-14614 | CF6: PAMIJEN SOKARAJA | CG6: -7.43527 | CH6: 109.27026 | CI6: CR-20250226-00000275
A7: 2 | B7: CMI | C7: RLC | D7: Nasional | E7: =+_xlfn.CONCAT(G7,"-",B7,"_",C7,"_",_xlfn.XLOOKUP(BP7,Account!M:M,Account!N:N)) -> #NAME? | F7: 45670 | G7: E3300061 | H7: ID-JT-05773 | I7: RSMARGONO | J7: 11 | K7: EMA | L7: JAWA TENGAH | M7: Kab. Banyumas | N7: KOMPLEK RS. MARGONO JL. JEND. SUDIRMAN PURWOKERTO | O7: -7.43475 | P7: 109.2674 | Q7: 13067.712 | R7: 55 | S7: IOH (hwei) | T7: Greenfield | U7: SST 4 Legs | V7: Dismantle Equipment | W7: Joko Dedoyo Kecil Liyanto | X7: 87861095209 | Y7: Dismantle | Z7: 45713 | AA7: 45720 | AB7: =IF(AA7="ds","Submit",IF(AA7="","NY Submit",IF(AA7<TODAY(),"Expired",IFERROR(DATEDIF(TODAY(),AA7,"d"),"")))) -> Expired | AD7: 45681 | AE7: 45686 | AH7: 45717 | AM7: 45727 | AO7: =+IF(AM7<>"","ATP App MS",IF(AJ7<>"","Inbound",IF(AH7<>"","Dismantle Perangkat",IF(AF7="Drop","Drop",IF(AE7<>"","Survey Report",IF(AD7<>"","Survey","NY Survey")))))) -> ATP App MS | AQ7: 45719 | AR7: 45719 | AS7: 45719 | AT7: 45765 | AU7: 45735 | AV7: 45735 | AW7: =+IF(AV7<>"","1st BOQ App on ISAAC",IF(AU7<>"","Upload 1st BOQ & BAN Isaac",IF(AT7="DRM","need DRM",IF(AT7<>"","BAN App",IF(AR7<>"","1st BOQ Pass TI",IF(AS7<>"","Engineering Structural Manager App",IF(AQ7<>"","1st BOQ Submit","NY Submit"))))))) -> 1st BOQ App on ISAAC | BD7: =+IF(BC7<>"","2nd BOQ App on ISAAC",IF(BB7<>"","Upload 2nd BOQ & BAN Isaac",IF(BA7="DRM","need DRM",IF(BA7<>"","BAN App",IF(AZ7<>"","Engineering Structural Manager App",IF(AY7<>"","2nd BOQ Pass TI",IF(AX7<>"","2nd BOQ Submit","NY Submit"))))))) -> NY Submit | BF7: 45689 | BG7: 45695 | BH7: JSA No.02/TSA/HSE/02/2025 | BI7: 45689 | BJ7: 45708 | BL7: =+IF(BG7<>"","Approved",IF(BF7<>"","Submit","NY Submit")) -> Approved | BM7: =+IF(BJ7<>"","Approved",IF(BI7<>"","Submit","NY Submit")) -> Approved | BN7: 45727 | BO7: 45803 | BP7: Dismantle Equipment | BQ7: EMAPO25-000808 | BR7: 45791 | BS7: =IF(AO7="Drop", "Drop", IF(ISBLANK(AV7), 0, IF(ISBLANK(BR7), DATEDIF(AV7,TODAY(),"d"), DATEDIF(AV7,BR7,"d") ) ) ) -> 56 | BV7: =IF(AO7="Drop", "Drop", IF(ISBLANK(BC7), 0, IF(ISBLANK(BU7), DATEDIF(BC7,TODAY(),"d"), DATEDIF(BC7,BU7,"d") ) ) ) -> 0 | BZ7: Complete | CE7: ID-JT-14614 | CF7: PAMIJEN SOKARAJA | CG7: -7.43527 | CH7: 109.27026 | CI7: CR-20250226-00000275
A8: 3 | B8: CMI | C8: RLC | D8: Nasional | E8: =+_xlfn.CONCAT(G8,"-",B8,"_",C8,"_",_xlfn.XLOOKUP(BP8,Account!M:M,Account!N:N)) -> #NAME? | F8: 45670 | G8: E3300061 | H8: ID-JT-05773 | I8: RSMARGONO | J8: 11 | K8: EMA | L8: JAWA TENGAH | M8: Kab. Banyumas | N8: KOMPLEK RS. MARGONO JL. JEND. SUDIRMAN PURWOKERTO | O8: -7.43475 | P8: 109.2674 | Q8: 13067.712 | R8: 55 | S8: IOH (hwei) | T8: Greenfield | U8: SST 4 Legs | V8: Relocation Equipment | W8: Joko Dedoyo Kecil Liyanto | X8: 87861095209 | Y8: Dismantle | Z8: 45713 | AA8: 45720 | AB8: =IF(AA8="ds","Submit",IF(AA8="","NY Submit",IF(AA8<TODAY(),"Expired",IFERROR(DATEDIF(TODAY(),AA8,"d"),"")))) -> Expired | AD8: 45681 | AE8: 45686 | AK8: 45719 | AL8: 45719 | AM8: 45727 | AO8: =+IF(AM8<>"","ATP App MS",IF(AL8<>"","OA/RFS",IF(AK8<>"","Install",IF(AH8<>"","Dismantle Perangkat",IF(AF8="Drop","Drop",IF(AE8<>"","Survey Report",IF(AD8<>"","Survey","NY Survey"))))))) -> ATP App MS | AQ8: 45719 | AR8: 45719 | AS8: 45719 | AT8: 45765 | AU8: 45735 | AV8: 45735 | AW8: =+IF(AV8<>"","1st BOQ App on ISAAC",IF(AU8<>"","Upload 1st BOQ & BAN Isaac",IF(AT8="DRM","need DRM",IF(AT8<>"","BAN App",IF(AR8<>"","1st BOQ Pass TI",IF(AS8<>"","Engineering Structural Manager App",IF(AQ8<>"","1st BOQ Submit","NY Submit"))))))) -> 1st BOQ App on ISAAC | BD8: =+IF(BC8<>"","2nd BOQ App on ISAAC",IF(BB8<>"","Upload 2nd BOQ & BAN Isaac",IF(BA8="DRM","need DRM",IF(BA8<>"","BAN App",IF(AZ8<>"","Engineering Structural Manager App",IF(AY8<>"","2nd BOQ Pass TI",IF(AX8<>"","2nd BOQ Submit","NY Submit"))))))) -> NY Submit | BF8: 45689 | BG8: 45695 | BH8: JSA No.02/TSA/HSE/02/2025 | BI8: 45689 | BJ8: 45708 | BL8: =+IF(BG8<>"","Approved",IF(BF8<>"","Submit","NY Submit")) -> Approved | BM8: =+IF(BJ8<>"","Approved",IF(BI8<>"","Submit","NY Submit")) -> Approved | BN8: 45727 | BO8: 45803 | BP8: Relocation Equipment | BQ8: EMAPO25-000809 | BR8: 45791 | BS8: =IF(AO8="Drop", "Drop", IF(ISBLANK(AV8), 0, IF(ISBLANK(BR8), DATEDIF(AV8,TODAY(),"d"), DATEDIF(AV8,BR8,"d") ) ) ) -> 56 | BV8: =IF(AO8="Drop", "Drop", IF(ISBLANK(BC8), 0, IF(ISBLANK(BU8), DATEDIF(BC8,TODAY(),"d"), DATEDIF(BC8,BU8,"d") ) ) ) -> 0 | BZ8: Complete | CE8: ID-JT-14614 | CF8: PAMIJEN SOKARAJA | CG8: -7.43527 | CH8: 109.27026 | CI8: CR-20250226-00000275
A9: 4 | B9: CMI | C9: RLC | D9: Nasional | E9: =+_xlfn.CONCAT(G9,"-",B9,"_",C9,"_",_xlfn.XLOOKUP(BP9,Account!M:M,Account!N:N)) -> #NAME? | F9: 45670 | G9: E3300061 | H9: ID-JT-05773 | I9: RSMARGONO | J9: 11 | K9: EMA | L9: JAWA TENGAH | M9: Kab. Banyumas | N9: KOMPLEK RS. MARGONO JL. JEND. SUDIRMAN PURWOKERTO | O9: -7.43475 | P9: 109.2674 | Q9: 13067.712 | R9: 55 | S9: IOH (hwei) | T9: Greenfield | U9: SST 4 Legs | V9: Rebuild_LOS Survey 14PWT0167_RSMARGONO to 14PWT0200_Purwadadi MT | W9: Joko Dedoyo Kecil Liyanto | X9: 87861095209 | Y9: Dismantle | Z9: 45713 | AA9: 45720 | AB9: =IF(AA9="ds","Submit",IF(AA9="","NY Submit",IF(AA9<TODAY(),"Expired",IFERROR(DATEDIF(TODAY(),AA9,"d"),"")))) -> Expired | AD9: 45737 | AE9: 45737 | AM9: 45737 | AO9: =+IF(AM9<>"","Survey LOS App",IF(AF9="Drop","Drop",IF(AE9<>"","Survey Report",IF(AD9<>"","Survey","NY Survey")))) -> Survey LOS App | AW9: =+IF(AV9<>"","1st BOQ App on ISAAC",IF(AU9<>"","Upload 1st BOQ & BAN Isaac",IF(AT9="DRM","need DRM",IF(AT9<>"","BAN App",IF(AR9<>"","1st BOQ Pass TI",IF(AS9<>"","Engineering Structural Manager App",IF(AQ9<>"","1st BOQ Submit","NY Submit"))))))) -> NY Submit | BD9: =+IF(BC9<>"","2nd BOQ App on ISAAC",IF(BB9<>"","Upload 2nd BOQ & BAN Isaac",IF(BA9="DRM","need DRM",IF(BA9<>"","BAN App",IF(AZ9<>"","Engineering Structural Manager App",IF(AY9<>"","2nd BOQ Pass TI",IF(AX9<>"","2nd BOQ Submit","NY Submit"))))))) -> NY Submit | BL9: =+IF(BG9<>"","Approved",IF(BF9<>"","Submit","NY Submit")) -> NY Submit | BM9: =+IF(BJ9<>"","Approved",IF(BI9<>"","Submit","NY Submit")) -> NY Submit | BP9: Rebuild_LOS Survey | BQ9: EMAPO25-000367 | BR9: 45726 | BS9: =IF(AO9="Drop", "Drop", IF(ISBLANK(AV9), 0, IF(ISBLANK(BR9), DATEDIF(AV9,TODAY(),"d"), DATEDIF(AV9,BR9,"d") ) ) ) -> 0 | BV9: =IF(AO9="Drop", "Drop", IF(ISBLANK(BC9), 0, IF(ISBLANK(BU9), DATEDIF(BC9,TODAY(),"d"), DATEDIF(BC9,BU9,"d") ) ) ) -> 0 | BZ9: Complete | CE9: 14PWT0200 | CF9: Purwadadi MT | CG9: -7.43527 | CH9: 109.27026
